2024-02-02 13:41:09,baseApi(line:53),ERROR|Traceback (most recent call last):
  File "C:\tools\python 36\lib\site-packages\urllib3\connection.py", line 175, in _new_conn
    (self._dns_host, self.port), self.timeout, **extra_kw
  File "C:\tools\python 36\lib\site-packages\urllib3\util\connection.py", line 95, in create_connection
    raise err
  File "C:\tools\python 36\lib\site-packages\urllib3\util\connection.py", line 85, in create_connection
    sock.connect(sa)
OSError: [WinError 10065] 套接字操作尝试一个无法连接的主机。

During handling of the above exception, another exception occurred:

Traceback (most recent call last):
  File "C:\tools\python 36\lib\site-packages\urllib3\connectionpool.py", line 722, in urlopen
    chunked=chunked,
  File "C:\tools\python 36\lib\site-packages\urllib3\connectionpool.py", line 416, in _make_request
    conn.request(method, url, **httplib_request_kw)
  File "C:\tools\python 36\lib\site-packages\urllib3\connection.py", line 244, in request
    super(HTTPConnection, self).request(method, url, body=body, headers=headers)
  File "C:\tools\python 36\lib\http\client.py", line 1239, in request
    self._send_request(method, url, body, headers, encode_chunked)
  File "C:\tools\python 36\lib\http\client.py", line 1285, in _send_request
    self.endheaders(body, encode_chunked=encode_chunked)
  File "C:\tools\python 36\lib\http\client.py", line 1234, in endheaders
    self._send_output(message_body, encode_chunked=encode_chunked)
  File "C:\tools\python 36\lib\http\client.py", line 1026, in _send_output
    self.send(msg)
  File "C:\tools\python 36\lib\http\client.py", line 964, in send
    self.connect()
  File "C:\tools\python 36\lib\site-packages\urllib3\connection.py", line 205, in connect
    conn = self._new_conn()
  File "C:\tools\python 36\lib\site-packages\urllib3\connection.py", line 187, in _new_conn
    self, "Failed to establish a new connection: %s" % e
urllib3.exceptions.NewConnectionError: <urllib3.connection.HTTPConnection object at 0x000002202344BEB8>: Failed to establish a new connection: [WinError 10065] 套接字操作尝试一个无法连接的主机。

During handling of the above exception, another exception occurred:

Traceback (most recent call last):
  File "C:\tools\python 36\lib\site-packages\requests\adapters.py", line 450, in send
    timeout=timeout
  File "C:\tools\python 36\lib\site-packages\urllib3\connectionpool.py", line 800, in urlopen
    method, url, error=e, _pool=self, _stacktrace=sys.exc_info()[2]
  File "C:\tools\python 36\lib\site-packages\urllib3\util\retry.py", line 592, in increment
    raise MaxRetryError(_pool, url, error or ResponseError(cause))
urllib3.exceptions.MaxRetryError: HTTPConnectionPool(host='42.192.62.8', port=8082): Max retries exceeded with url: //account/sLogin (Caused by NewConnectionError('<urllib3.connection.HTTPConnection object at 0x000002202344BEB8>: Failed to establish a new connection: [WinError 10065] 套接字操作尝试一个无法连接的主机。',))

During handling of the above exception, another exception occurred:

Traceback (most recent call last):
  File "C:\DeliverySystem完整代码\common\baseApi.py", line 45, in request_send
    **kwargs)  # ** 展开关键字参数--解包
  File "C:\tools\python 36\lib\site-packages\requests\api.py", line 61, in request
    return session.request(method=method, url=url, **kwargs)
  File "C:\tools\python 36\lib\site-packages\requests\sessions.py", line 529, in request
    resp = self.send(prep, **send_kwargs)
  File "C:\tools\python 36\lib\site-packages\requests\sessions.py", line 645, in send
    r = adapter.send(request, **kwargs)
  File "C:\tools\python 36\lib\site-packages\requests\adapters.py", line 519, in send
    raise ConnectionError(e, request=request)
requests.exceptions.ConnectionError: HTTPConnectionPool(host='42.192.62.8', port=8082): Max retries exceeded with url: //account/sLogin (Caused by NewConnectionError('<urllib3.connection.HTTPConnection object at 0x000002202344BEB8>: Failed to establish a new connection: [WinError 10065] 套接字操作尝试一个无法连接的主机。',))

